<?xml version="1.0" encoding="UTF-8" ?>
<testsuites>
    <testsuite name="LuaUnit" id="00001" package="" hostname="localhost" tests="15" timestamp="2016-03-21T23:00:32" time="0.000" errors="5" failures="5">
        <properties>
            <property name="Lua Version" value="Lua 5.1"/>
            <property name="LuaUnit Version" value="3.2"/>
        </properties>
        <testcase classname="TestAnotherThing" name="TestAnotherThing.testErr1" time="0.000">
            <error type="test/test_with_err_fail_pass.lua:49: attempt to perform arithmetic on a table value">
                <![CDATA[stack traceback:
	[C]: in function 'xpcall']]></error>
        </testcase>
        <testcase classname="TestAnotherThing" name="TestAnotherThing.testErr2" time="0.000">
            <error type="test/test_with_err_fail_pass.lua:53: attempt to perform arithmetic on a table value">
                <![CDATA[stack traceback:
	[C]: in function 'xpcall']]></error>
        </testcase>
        <testcase classname="TestAnotherThing" name="TestAnotherThing.testFail1" time="0.000">
            <failure type="test/test_with_err_fail_pass.lua:41: expected: 0, actual: 2">
                <![CDATA[stack traceback:
	test/test_with_err_fail_pass.lua:41: in function 'TestAnotherThing.testFail1']]></failure>
        </testcase>
        <testcase classname="TestAnotherThing" name="TestAnotherThing.testFail2" time="0.000">
            <failure type="test/test_with_err_fail_pass.lua:45: expected: 0, actual: 3">
                <![CDATA[stack traceback:
	test/test_with_err_fail_pass.lua:45: in function 'TestAnotherThing.testFail2']]></failure>
        </testcase>
        <testcase classname="TestAnotherThing" name="TestAnotherThing.testSuccess1" time="0.000">
        </testcase>
        <testcase classname="TestAnotherThing" name="TestAnotherThing.testSuccess2" time="0.000">
        </testcase>
        <testcase classname="TestSomething" name="TestSomething.testErr1" time="0.000">
            <error type="test/test_with_err_fail_pass.lua:23: attempt to perform arithmetic on a table value">
                <![CDATA[stack traceback:
	[C]: in function 'xpcall']]></error>
        </testcase>
        <testcase classname="TestSomething" name="TestSomething.testErr2" time="0.000">
            <error type="test/test_with_err_fail_pass.lua:27: attempt to perform arithmetic on a table value">
                <![CDATA[stack traceback:
	[C]: in function 'xpcall']]></error>
        </testcase>
        <testcase classname="TestSomething" name="TestSomething.testFail1" time="0.000">
            <failure type="test/test_with_err_fail_pass.lua:15: expected: 0, actual: 2">
                <![CDATA[stack traceback:
	test/test_with_err_fail_pass.lua:15: in function 'TestSomething.testFail1']]></failure>
        </testcase>
        <testcase classname="TestSomething" name="TestSomething.testFail2" time="0.000">
            <failure type="test/test_with_err_fail_pass.lua:19: expected: 0, actual: 3">
                <![CDATA[stack traceback:
	test/test_with_err_fail_pass.lua:19: in function 'TestSomething.testFail2']]></failure>
        </testcase>
        <testcase classname="TestSomething" name="TestSomething.testSuccess1" time="0.000">
        </testcase>
        <testcase classname="TestSomething" name="TestSomething.testSuccess2" time="0.000">
        </testcase>
        <testcase classname="[TestFunctions]" name="testFuncErr1" time="0.000">
            <error type="test/test_with_err_fail_pass.lua:66: attempt to perform arithmetic on a table value">
                <![CDATA[stack traceback:
	[C]: in function 'xpcall']]></error>
        </testcase>
        <testcase classname="[TestFunctions]" name="testFuncFail1" time="0.000">
            <failure type="test/test_with_err_fail_pass.lua:62: expected: 0, actual: 3">
                <![CDATA[stack traceback:
	test/test_with_err_fail_pass.lua:62: in function 'testFuncFail1']]></failure>
        </testcase>
        <testcase classname="[TestFunctions]" name="testFuncSuccess1" time="0.000">
        </testcase>
    <system-out/>
    <system-err/>
    </testsuite>
</testsuites>
